Workbook

Sheet Usevi
B1: JEČAM | D1: Obradivo zemljište (ha): | F1: 0
A3: AGROTEHNIKA I TROŠKOVNIK | E3: OPTIMALNO
A4: R. br. | B4: Tehnološke operacije i korišćeni materijal | C4: Operacija u mesecu | D4: Trošak po kg ili litru (EUR) | E4: Optimalna potrošnja kg ili l/ha | F4: Optimalni troškovi tehnoloških operacija/ha (EUR)
A5: 1 | B5: Transport đubriva | C5: X | D5: 1.23 | E5: 1.2 | F5: =E5*D5 -> 1.476
B6: NPK đubrivo 15:15:15 | D6: 0.35 | E6: 300 | F6: =E6*D6 -> 105
A7: 2 | B7: Rasipanje mineralnih đubriva | C7: X | D7: 1.23 | E7: 1.16 | F7: =E7*D7 -> 1.4268
A8: 3 | B8: Oranje | C8: X | D8: 1.23 | E8: 20.28 | F8: =E8*D8 -> 24.9444
A9: 4 | B9: Tanjiranje | C9: X | D9: 1.23 | E9: 3.78 | F9: =E9*D9 -> 4.6494
A10: 5 | B10: Drljanje | C10: X | D10: 1.23 | E10: 2.28 | F10: =E10*D10 -> 2.8044
A11: 6 | B11: Transport semena | C11: X | D11: 1.23 | E11: 0.96 | F11: =E11*D11 -> 1.1808
B12: Seme | D12: 0.4 | E12: 200 | F12: =E12*D12 -> 80
A13: 7 | B13: Setva | C13: X | D13: 1.23 | E13: 3.36 | F13: =E13*D13 -> 4.1328
A14: 8 | B14: Transport đubriva | C14: II | D14: 1.23 | E14: 0.84 | F14: =E14*D14 -> 1.0332
B15: Đubrivo KAN 27% N | D15: 0.26 | E15: 200 | F15: =E15*D15 -> 52
A16: 9 | B16: Rasipanje mineralnih đubriva | C16: II | D16: 1.23 | E16: 1.16 | F16: =E16*D16 -> 1.4268
A17: 10 | B17: Transport vode - 2 puta | C17: V | D17: 1.23 | E17: =0.96*2 -> 1.92 | F17: =E17*D17 -> 2.3616
A18: 11 | B18: Zaštita bilja - 2 puta | C18: V | D18: 1.23 | E18: =2*0.92 -> 1.84 | F18: =E18*D18 -> 2.2632
B19: Meteor (herbicid) ili | E19: 0.01 | F19: =E19*D19 -> 0
B20: Sekator (herbicid) - 1 put | D20: 94.28 | E20: 0.15 | F20: =E20*D20 -> 14.142
B21: Decis (insekticid) ili | E21: 0 | F21: =E21*D21 -> 0
B22: Falcon (fungicid) - 1 put | D22: 41.26 | E22: 0.6 | F22: =E22*D22 -> 24.756
A23: 12 | B23: Žetva kombajnom | C23: VI-VII | E23: 0 | F23: =E23*D23 -> 0
A24: 13 | B24: Transport ječma | C24: VI-VII | D24: 1.23 | E24: 8 | F24: =E24*D24 -> 9.84
A25: 14 | B25: Balranje slame (bale) | C25: VI-VII | D25: 1.23 | E25: 0 | F25: =E25*D25 -> 0
A26: 15 | B26: Transport slame | C26: VI-VII | D26: 1.23 | E26: 18 | F26: =E26*D26 -> 22.14
A27: UKUPNI TROŠKOVI | F27: =SUM(F5:F26) -> 355.5774 | G27: =F1*F27 -> 0
A28: Potrošnja goriva | E28: =E5+E7+E8+E9+E10+E11+E13+E14+E16+E17+E18+E24+E26 -> 64.78 | G28: Ukupno
A30: Ječam se može sejati u jesen i u proleće. Jesenjom setvom koja je u praksi pretežno zastupljena, postižu se znatno viši prinosi nego proletnjom. Tretiranje hemijskim sredstvima se vrši po potrebi. U praksi se najčešće primenjuje jedno prskanje (herbicidom ili insekticidom) u zavisnosti od potrebe.
B36: PŠENICA | D36: Obradivo zemljište (ha): | F36: 0
A38: AGROTEHNIKA I TROŠKOVNIK | E38: OPTIMALNO
A39: R. br. | B39: Tehnološke operacije i korišćeni materijal | C39: Operacija u mesecu | D39: Trošak po kg ili litru (EUR) | E39: Optimalna potrošnja kg ili l/ha | F39: Optimalni troškovi tehnoloških operacija/ha (EUR)
A40: 1 | B40: Transport đubriva | C40: X | D40: 1.23 | E40: 1.2 | F40: =E40*D40 -> 1.476
B41: NPK đubrivo 15:15:15 | D41: 0.35 | E41: 300 | F41: =E41*D41 -> 105
A42: 2 | B42: Rasipanje mineralnih đubriva | C42: X | D42: 1.23 | E42: 1.16 | F42: =E42*D42 -> 1.4268
A43: 3 | B43: Oranje | C43: X | D43: 1.23 | E43: 20.28 | F43: =E43*D43 -> 24.9444
A44: 4 | B44: Tanjiranje | C44: X | D44: 1.23 | E44: 3.78 | F44: =E44*D44 -> 4.6494
A45: 5 | B45: Drljanje | C45: X | D45: 1.23 | E45: 2.28 | F45: =E45*D45 -> 2.8044
A46: 6 | B46: Transport semena | C46: X | D46: 1.23 | E46: 1.2 | F46: =E46*D46 -> 1.476
B47: Seme | D47: 0.44 | E47: 280 | F47: =E47*D47 -> 123.2
A48: 7 | B48: Setva | C48: X | D48: 1.23 | E48: 3.36 | F48: =E48*D48 -> 4.1328
...

Sheet Povrće
B1: KROMPIR | D1: Obradivo zemljište (ha): | F1: 0
A3: AGROTEHNIKA I TROŠKOVNIK | E3: OPTIMALNO
A4: R. br. | B4: Tehnološke operacije i korišćeni materijal | C4: Operacija u mesecu | D4: Trošak po kg ili litru (EUR) | E4: Optimalna potrošnja kg ili l/ha | F4: Optimalni troškovi tehnoloških operacija/ha (EUR)
A5: 1 | B5: Utovar stajnjaka | C5: VII | D5: 1.23 | E5: 11.32 | F5: =E5*D5 -> 13.9236
A6: 2 | B6: Transport i rasturanje stajnjaka | C6: VII | D6: 1.23 | E6: 60 | F6: =E6*D6 -> 73.8
A7: 3 | B7: Zaoravanje strnjike | C7: VII | D7: 1.23 | E7: 17.58 | F7: =E7*D7 -> 21.6234
A8: 4 | B8: Tanjiranje | C8: IX | D8: 1.23 | E8: 3.9 | F8: =E8*D8 -> 4.797
A9: 5 | B9: Transport đubriva | C9: XI | D9: 1.23 | E9: 2.16 | F9: =E9*D9 -> 2.6568
B10: NPK đubrivo 8:16:24 | D10: 0.34 | E10: 500 | F10: =E10*D10 -> 170
A11: 6 | B11: Rasipanje mineralnih đubriva | C11: XI | D11: 1.23 | E11: 1.16 | F11: =E11*D11 -> 1.4268
A12: 7 | B12: Oranje | C12: XI | D12: 1.23 | E12: 21.66 | F12: =E12*D12 -> 26.6418
A13: 8 | B13: Predsetvena priprema zemljišta | C13: III | D13: 1.23 | E13: 2.16 | F13: =E13*D13 -> 2.6568
A14: 9 | B14: Transport semena | C14: III | D14: 1.23 | E14: 0.57 | F14: =E14*D14 -> 0.7011
B15: Seme | D15: 0.65 | E15: 2500 | F15: =E15*D15 -> 1625
A16: 10 | B16: Sađenje semena | C16: III | D16: 1.23 | E16: 4 | F16: =E16*D16 -> 4.92
A17: 11 | B17: Transport vode | C17: III | D17: 1.23 | E17: 0.96 | F17: =E17*D17 -> 1.1808
A18: 12 | B18: Zaštita bilja | C18: III | D18: 1.23 | E18: 0.92 | F18: =E18*D18 -> 1.1316
B19: Stomp ili | D19: 8.88 | E19: 5 | F19: =E19*D19 -> 44.4
B20: Prometrin | E20: 0 | F20: =E20*D20 -> 0
A21: 13 | B21: Transport đubriva | C21: V | D21: 1.23 | E21: 0.9 | F21: =E21*D21 -> 1.107
B22: Đubrivo urea 46% N | D22: 0.32 | E22: 300 | F22: =E22*D22 -> 96
A23: 14 | B23: Međuredno kultiviranje sa đubrenjem | C23: V | D23: 1.23 | E23: 2.92 | F23: =E23*D23 -> 3.5916
A24: 15 | B24: Transport vode - 4 puta | C24: V-VIII | D24: 1.23 | E24: 3.84 | F24: =E24*D24 -> 4.7232
A25: 16 | B25: Zaštita bilja - 4 puta | C25: V-VIII | D25: 1.23 | E25: 3.68 | F25: =E25*D25 -> 4.5264
B26: Sencor + | D26: 56.52 | E26: 0.5 | F26: =E26*D26 -> 28.26
B27: Confidor - 1. put | D27: 170.37 | E27: 0.2 | F27: =E27*D27 -> 34.074
B28: Confidor + | D28: 170.37 | E28: 0.2 | F28: =E28*D28 -> 34.074
B29: Ridomil - 2. put | D29: 26.64 | E29: 2.5 | F29: =E29*D29 -> 66.6
B30: Ridomil + | D30: 26.64 | E30: 2.5 | F30: =E30*D30 -> 66.6
B31: Confidor - 3. put | D31: 170.37 | E31: 0.2 | F31: =E31*D31 -> 34.074
B32: Equation - 4. put | D32: 111.02 | E32: 0.4 | F32: =E32*D32 -> 44.408
A33: 17 | B33: Navodnjavanje - 2 puta | C33: V-VII | D33: 1.23 | E33: 80 | F33: =E33*D33 -> 98.4
A34: 18 | B34: Drugo međuredno kultiviranje | C34: VI | D34: 1.23 | E34: 2.92 | F34: =E34*D34 -> 3.5916
A35: 19 | B35: Vađenje krompira | C35: VIII | D35: 1.23 | E35: 16 | F35: =E35*D35 -> 19.68
A36: 20 | B36: Transport krompira | C36: VIII | D36: 1.23 | E36: 20 | F36: =E36*D36 -> 24.6
A37: UKUPNI TROŠKOVI | F37: =SUM(F5:F36) -> 2559.1695 | G37: =F1*F37 -> 0
A38: Potrošnja goriva | E38: =E5+E6+E7+E8+E9+E11+E12+E13+E14+E16+E17+E18+E21+E23+E24+E25+E33+E34+E36 -> 240.65 | G38: Ukupno
A40: Krompir se sadi krajem marta meseca. Prinosi se kreću od 15-25 t/ha. Vegetacija za mlad krompir iznosi oko 60-70 dana, a za merkantilni krompir do 150 dana.
B44: PASULJ | D44: Obradivo zemljište (ha): | F44: 0
A46: AGROTEHNIKA I TROŠKOVNIK | E46: OPTIMALNO
...

Sheet Voće
B1: ŠLJIVA - ekstenzivan zasad | D1: Obradivo zemljište (ha): | F1: 0
A3: AGROTEHNIKA I TROŠKOVNIK | E3: OPTIMALNO
A4: R. br. | B4: Tehnološke operacije i korišćeni materijal | C4: Operacija u mesecu | D4: Trošak po kg ili litru (EUR) | E4: Optimalna potrošnja kg ili l/ha | F4: Optimalni troškovi tehnoloških operacija/ha (EUR)
A5: 1 | B5: Transport đubriva | C5: III | D5: 1.23 | E5: 2.16 | F5: =(E5*D5) -> 2.6568
B6: NPK đubrivo 8:16:24 | D6: 0.34 | E6: 100 | F6: =(E6*D6) -> 34
A7: 2 | B7: Rasipanje mineralnih đubriva | C7: III | D7: 1.23 | E7: 1.16 | F7: =(E7*D7) -> 1.4268
A8: 3 | B8: Kultiviranje/košenje - 2 puta | C8: IV/VI,VII | D8: 1.23 | E8: 10.56 | F8: =(E8*D8) -> 12.9888
A9: 4 | B9: Transport đubriva | C9: IV | D9: 1.23 | E9: 2.16 | F9: =(E9*D9) -> 2.6568
B10: Đubrivo KAN 27% N | D10: 0.26 | E10: 100 | F10: =(E10*D10) -> 26
A11: 5 | B11: Rasipanje mineralnih đubriva | C11: IV | D11: 1.23 | E11: 1.16 | F11: =(E11*D11) -> 1.4268
A12: 6 | B12: Transport vode - 2 puta | C12: II-IV | D12: 1.23 | E12: 1.56 | F12: =(E12*D12) -> 1.9188
A13: 7 | B13: Zaštita bilja - 2 puta | C13: II-IV | D13: 1.23 | E13: 1.84 | F13: =(E13*D13) -> 2.2632
B14: Bakarni oksi hlorid + | D14: 10.01 | E14: 6 | F14: =(E14*D14) -> 60.06
B15: Chorus - 1. put | C15: II | D15: 115.87 | E15: 0.2 | F15: =(E15*D15) -> 23.174
B16: Perfection + | D16: 9.19 | E16: 1.5 | F16: =(E16*D16) -> 13.785
B17: Ditan - 2. put | C17: IV | D17: 6.46 | E17: 2.5 | F17: =(E17*D17) -> 16.15
A18: 8 | B18: Transport šljive | C18: VII-IX | D18: 1.23 | E18: 8 | F18: =(E18*D18) -> 9.84
A19: UKUPNI TROŠKOVI | F19: =SUM(F5:F18) -> 208.347 | G19: =F1*F19 -> 0
A20: Potrošnja goriva | E20: =E5+E7+E8+E9+E11+E12+E13+E18 -> 28.6 | G20: Ukupno
A22: Komentar:
B26: ŠLJIVA - intenzivan zasad | D26: Obradivo zemljište (ha): | F26: 0
A28: AGROTEHNIKA I TROŠKOVNIK | E28: OPTIMALNO
A29: R. br. | B29: Tehnološke operacije i korišćeni materijal | C29: Operacija u mesecu | D29: Trošak po kg ili litru (EUR) | E29: Optimalna potrošnja kg ili l/ha | F29: Optimalni troškovi tehnoloških operacija/ha (EUR)
A30: 1 | B30: Površinska obrada zemljišta | C30: XI | D30: 1.23 | E30: 15 | F30: =E30*D30 -> 18.45
A31: 2 | B31: Transport đubriva | C31: III | D31: 1.23 | E31: 2.16 | F31: =(E31*D31) -> 2.6568
B32: NPK đubrivo 8:16:24 | D32: 0.34 | E32: 500 | F32: =(E32*D32) -> 170
A33: 3 | B33: Rasipanje mineralnih đubriva | C33: III | D33: 1.23 | E33: 1.16 | F33: =(E33*D33) -> 1.4268
A34: 4 | B34: Međuredno kultiviranje - 4 puta | C34: III,IV,VI,VII | D34: 1.23 | E34: 10.56 | F34: =(E34*D34) -> 12.9888
A35: 5 | B35: Transport đubriva | C35: IV | D35: 1.23 | E35: 2.16 | F35: =(E35*D35) -> 2.6568
B36: Đubrivo KAN 27% N | D36: 0.26 | E36: 500 | F36: =(E36*D36) -> 130
A37: 6 | B37: Rasipanje mineralnih đubriva | C37: IV | D37: 1.23 | E37: 1.16 | F37: =(E37*D37) -> 1.4268
A38: 7 | B38: Transport vode - 7 puta | C38: II-X | D38: 1.23 | E38: 5.46 | F38: =(E38*D38) -> 6.7158
A39: 8 | B39: Zaštita bilja - 7 puta | C39: II-X | D39: 1.23 | E39: 6.44 | F39: =(E39*D39) -> 7.9212
B40: Crveno ulje - 1. put | C40: II | D40: 6.06 | E40: 30 | F40: =(E40*D40) -> 181.8
B41: Chorus + | D41: 115.87 | E41: 0.2 | F41: =(E41*D41) -> 23.174
B42: Kubik - 2. put | C42: III | D42: 15.5 | E42: 1 | F42: =(E42*D42) -> 15.5
B43: Perfection - 3. put | C43: IV | D43: 9.19 | E43: 1.5 | F43: =(E43*D43) -> 13.785
B44: Ditan + | D44: 6.46 | E44: 2.5 | F44: =(E44*D44) -> 16.15
B45: Nurel - 4. put | C45: V | D45: 12.11 | E45: 1 | F45: =(E45*D45) -> 12.11
B46: Captan + | D46: 11.71 | E46: 3 | F46: =(E46*D46) -> 35.13
...

Sheet Plastenici
B1: PARADAJZ | F1: Broj plastenika | G1: 0
F2: Veličina plastenika (20*5 m2)
A3: R. br. | B3: Tehnološke operacije / korišćeni materijal | C3: Operacija u mesecu | D3: Potrošnja kg ili l /plastenik | E3: Trošak po kg ili l (EUR) | F3: Ukupni troškovi/plastenik | G3: Ukupni troškovi /obradivo zemljište
A4: 1 | B4: Materijal
B5: Seme | C5: II | D5: 400 | E5: 0.097 | F5: =+D5*E5 -> 38.8 | G5: =+F5*$G$1 -> 0
A6: 2 | B6: Đubrivo
B7: N:P:K 15:15:15 | C7: III | D7: 10 | E7: 0.35 | F7: =+D7*E7 -> 3.5 | G7: =+F7*$G$1 -> 0
B8: Kemira 15:30:15 | C8: V | D8: 4 | E8: 2.18 | F8: =+D8*E8 -> 8.72 | G8: =+F8*$G$1 -> 0
B9: Kemira 10:15:26 | C9: V-VIII | D9: 20 | E9: 1.98 | F9: =+D9*E9 -> 39.6 | G9: =+F9*$G$1 -> 0
B10: Vuksal super | C10: V-VIII | D10: 0.1 | E10: 2.83 | F10: =+D10*E10 -> 0.283 | G10: =+F10*$G$1 -> 0
B11: Jara kalcinit | C11: V-VIII | D11: 10 | E11: 0.73 | F11: =+D11*E11 -> 7.3 | G11: =+F11*$G$1 -> 0
A12: 3 | B12: Pesticidi | C12: III-VIII
B13: Equation - 2 puta | D13: 0.008 | E13: 111.02 | F13: =+D13*E13 -> 0.88816 | G13: =+F13*$G$1 -> 0
B14: Antracol - 2 puta | D14: 0.06 | E14: 11.24 | F14: =+D14*E14 -> 0.6744 | G14: =+F14*$G$1 -> 0
B15: Ripcord - 2 puta | D15: 0.06 | E15: 43.6 | F15: =+D15*E15 -> 2.616 | G15: =+F15*$G$1 -> 0
B16: Ridomil - 2 puta | D16: 0.06 | E16: 22.64 | F16: =+D16*E16 -> 1.3584 | G16: =+F16*$G$1 -> 0
B17: Rovocid | D17: 1 | E17: 2.83 | F17: =+D17*E17 -> 2.83 | G17: =+F17*$G$1 -> 0
A18: 4 | B18: Konopac-vezivanje struka u plasten. | D18: 10 | E18: 2.41 | F18: =+D18*E18 -> 24.1 | G18: =+F18*$G$1 -> 0
A19: 5 | B19: Navodnjavanje | C19: III-VIII | D19: 20 | E19: 1.17 | F19: =+D19*E19 -> 23.4 | G19: =+F19*$G$1 -> 0
A20: 6 | B20: Usluge | H20: BROJ STRUKA U PLASTENIKU
B21: 1. Obrada | C21: III-VIII | D21: 3 | E21: 1.17 | F21: =+D21*E21 -> 3.51 | G21: =+F21*$G$1 -> 0
B22: 2. Zaštita (8x) | C22: III-VIII | D22: 4 | E22: 1.17 | F22: =+D22*E22 -> 4.68 | G22: =+F22*$G$1 -> 0 | H22: 400
B23: 3. Transport | C23: VI-IX | F23: 0 | G23: =+F23*$G$1 -> 0 | H23: TROŠAK PO STRUKU
A24: UKUPNI TROŠKOVI | F24: =SUM(F5:F23) -> 162.25996 | G24: =SUM(G5:G23) -> 0 | H24: =+F24/H22 -> 0.4056499
B26: PAPRIKA SLATKA | F26: Broj plastenika | G26: 0
F27: Veličina plastenika (20*5 m2)
A28: R. br. | B28: Tehnološke operacije / korišćeni materijal | C28: Operacija u mesecu | D28: Potrošnja kg ili l /plastenik | E28: Trošak po kg ili l (EUR) | F28: Ukupni troškovi/plastenik | G28: Ukupni troškovi /obradivo zemljište
A29: 1 | B29: Materijal
B30: Seme | C30: II | D30: 640 | E30: 0.078 | F30: =+D30*E30 -> 49.92 | G30: =+F30*$G$26 -> 0
A31: 2 | B31: Đubrivo
B32: N:P:K 15:15:15 | C32: III | D32: 10 | E32: 0.35 | F32: =+D32*E32 -> 3.5 | G32: =+F32*$G$26 -> 0
B33: Kemira 15:30:15 | C33: V | D33: 4 | E33: 2.18 | F33: =+D33*E33 -> 8.72 | G33: =+F33*$G$26 -> 0
B34: Kemira 10:15:26 | C34: V-VIII | D34: 20 | E34: 1.98 | F34: =+D34*E34 -> 39.6 | G34: =+F34*$G$26 -> 0
B35: Vuksal super | C35: V-VIII | D35: 0.1 | E35: 2.83 | F35: =+D35*E35 -> 0.283 | G35: =+F35*$G$26 -> 0
B36: Jara kalcinit | C36: V-VIII | D36: 10 | E36: 0.73 | F36: =+D36*E36 -> 7.3 | G36: =+F36*$G$26 -> 0
A37: 3 | B37: Pesticidi | C37: III-VIII
B38: Equation - 1 put | D38: 0.004 | E38: 111.02 | F38: =+D38*E38 -> 0.44408 | G38: =+F38*$G$26 -> 0
B39: Bakarni oksihlorid - 1 put | D39: 0.05 | E39: 10.01 | F39: =+D39*E39 -> 0.5005 | G39: =+F39*$G$26 -> 0
B40: Aktara + | D40: 0.006 | E40: 292.69 | F40: =+D40*E40 -> 1.75614 | G40: =+F40*$G$26 -> 0
B41: Ditan - 1 put | D41: 0.025 | E41: 6.46 | F41: =+D41*E41 -> 0.1615 | G41: =+F41*$G$26 -> 0
...

Sheet Ostalo
B1: LIVADE | D1: Obradivo zemljište (ha): | F1: 0
A3: AGROTEHNIKA I TROŠKOVNIK | E3: OPTIMALNO
A4: R. br. | B4: Tehnološke operacije i korišćeni materijal | C4: Operacija u mesecu | D4: Trošak po kg ili litru (EUR) | E4: Optimalna potrošnja kg ili l/ha | F4: Optimalni troškovi tehnoloških operacija/ha (EUR)
A5: 1 | B5: Zaštita bilja - rodencidi | C5: III | E5: 0 | F5: =D5*E5 -> 0
A6: 2 | B6: Košenje - žetva | C6: V,VII,IX | E6: 0 | F6: =D6*E6 -> 0
A7: 3 | B7: Sakupljanje | C7: V,VII,IX | E7: 0 | F7: =D7*E7 -> 0
A8: 4 | B8: Baliranje livadskog sena (bale) | C8: V,VII,IX | E8: 0 | F8: =D8*E8 -> 0
A9: 5 | B9: Transport sena | C9: V,VII,IX | D9: 1.23 | E9: 18 | F9: =D9*E9 -> 22.14
A10: 6 | B10: Utovar stajnjaka (1/4) | C10: X | D10: 1.23 | E10: 1.42 | F10: =D10*E10 -> 1.7466
A11: 7 | B11: Transport i rasturanje stajnjaka | C11: X | D11: 1.23 | E11: 7.5 | F11: =D11*E11 -> 9.225
A12: UKUPNI TROŠKOVI | F12: =SUM(F5:F11) -> 33.1116 | G12: =F1*F12 -> 0
A13: Potrošnja goriva | E13: =E9+E10+E11 -> 26.92 | G13: Ukupno
A15: U praksi preovlađuju prirodne livade. Ukoliko postoje veštačke livade, u tehnološku kartu treba uključiti troškove goriva za osnovnu i dopunsku obradu zemljišta, troškove semena i goriva za setvu. Troškovi košenja, sakupljanja i baliranja livadskog sena nisu uključeni, pošto većina gazdinstava plaća ove usluge. Prosečan prinos se kreće oko 4 t/ha.
B20: ŠAMPINJONI | F20: 0
A22: AGROTEHNIKA I TROŠKOVNIK | E22: OPTIMALNO
A23: R. br. | B23: Tehnološke operacije i korišćeni materijal | C23: Operacija u mesecu | D23: Trošak po kg ili litru (EUR) | E23: Optimalna potrošnja kg ili l/košnice | F23: Optimalni troškovi tehnoloških operacija/košnice (EUR)
A24: 1 | B24: Korišćeni materijali
B25: Kompost sa micelijumom | D25: 0.11 | E25: 18 | F25: =E25*D25 -> 1.98
B26: Treset | D26: 0.08 | E26: 5 | F26: =E26*D26 -> 0.4
A27: 2 | B27: Zaštita šampinjona
B28: Ditan | D28: 6.46 | E28: 0.002 | F28: =E28*D28 -> 0.01292
B29: Miraž | D29: 23.66 | E29: 0.002 | F29: =E29*D29 -> 0.04732
B30: Dimilin | D30: 140.65 | E30: 0.002 | F30: =E30*D30 -> 0.2813
B31: Nuvan | D31: 11.3 | E31: 0.001 | F31: =E31*D31 -> 0.0113
B32: Actelic | D32: 44.09 | E32: 0.001 | F32: =E32*D32 -> 0.04409
A33: 3 | B33: Transport šampinjona | E33: 0 | F33: =E33*D33 -> 0
A34: UKUPNI TROŠKOVI | F34: =SUM(F24:F33) -> 2.77693 | G34: =F20*F34 -> 0
A35: Potrošnja goriva | E35: =E33 -> 0 | G35: Ukupno
A37: Prosečan prinos šampinjona po jednoj vreći kreće se od 3-6 kg. Od momenta stavljana micelijuma u kompost pa do početka branja protekne 30 dana. Šampinjoni se beru narednih 30 dana.

Sheet Zalihe na parceli
A1: Red. broj | B1: Usevi | C1: M e s e c i | AA1: Ukupno
C2: I | E2: II | G2: III | I2: IV | K2: V | M2: VI | O2: VII | Q2: VIII | S2: IX | U2: X | W2: XI | Y2: XII
C3: iznos € | D3: ha/struka | E3: iznos € | F3: ha/struka | G3: iznos € | H3: ha/struka | I3: iznos € | J3: ha/struka | K3: iznos € | L3: ha/struka | M3: iznos € | N3: ha/struka | O3: iznos € | P3: ha/struka | Q3: iznos € | R3: ha/struka | S3: iznos € | T3: ha/struka | U3: iznos € | V3: ha/struka | W3: iznos € | X3: ha/struka | Y3: iznos € | Z3: ha/struka | AA3: iznos € | AB3: ha
A4: 1 | B4: Ječam | C4: =U4 -> 225.6146 | E4: =U4+Usevi!F14+Usevi!F15+Usevi!F16 -> 280.0746 | G4: =E4 -> 280.0746 | I4: =E4 -> 280.0746 | K4: =E4+Usevi!F17+Usevi!F18+Usevi!F19+Usevi!F20+Usevi!F21 -> 298.8414 | M4: =K4 -> 298.8414 | O4: 0 | Q4: 0 | S4: 0 | U4: =Usevi!F5+Usevi!F6+Usevi!F7+Usevi!F8+Usevi!F9+Usevi!F10+Usevi!F11+Usevi!F12+Usevi!F13 -> 225.6146 | W4: =U4 -> 225.6146 | Y4: =U4 -> 225.6146 | AA4: =C4*D4+E4*F4+G4*H4+I4*J4+K4*L4+M4*N4+O4*P4+Q4*R4+S4*T4+U4*V4+W4*X4+Y4*Z4 -> 0 | AB4: =D4+F4+H4+J4+L4+N4+P4+R4+T4+V4+X4+Z4 -> 0
A5: 2 | B5: Pšenica | C5: =U5 -> 269.1098 | E5: =U5+Usevi!F49+Usevi!F50+Usevi!F51 -> 323.5698 | G5: =E5 -> 323.5698 | I5: =E5 -> 323.5698 | K5: =E5+Usevi!F52+Usevi!F53+Usevi!F54+Usevi!F55+Usevi!F56 -> 342.3366 | M5: =K5 -> 342.3366 | O5: 0 | Q5: 0 | S5: 0 | U5: =Usevi!F40+Usevi!F41+Usevi!F42+Usevi!F43+Usevi!F44+Usevi!F45+Usevi!F46+Usevi!F47+Usevi!F48 -> 269.1098 | W5: =U5 -> 269.1098 | Y5: =U5 -> 269.1098 | AA5: =C5*D5+E5*F5+G5*H5+I5*J5+K5*L5+M5*N5+O5*P5+Q5*R5+S5*T5+U5*V5+W5*X5+Y5*Z5 -> 0 | AB5: =D5+F5+H5+J5+L5+N5+P5+R5+T5+V5+X5+Z5 -> 0
A6: 3 | B6: Tritikal | C6: =U6 -> 241.9098 | E6: =U6+Usevi!F82+Usevi!F83+Usevi!F84 -> 296.3698 | G6: =E6 -> 296.3698 | I6: =E6 -> 296.3698 | K6: =E6+Usevi!F85+Usevi!F86+Usevi!F87+Usevi!F88+Usevi!F89 -> 315.1366 | M6: =K6 -> 315.1366 | O6: 0 | Q6: 0 | S6: 0 | U6: =Usevi!F73+Usevi!F74+Usevi!F75+Usevi!F76+Usevi!F77+Usevi!F78+Usevi!F79+Usevi!F80+Usevi!F81 -> 241.9098 | W6: =U6 -> 241.9098 | Y6: =U6 -> 241.9098 | AA6: =C6*D6+E6*F6+G6*H6+I6*J6+K6*L6+M6*N6+O6*P6+Q6*R6+S6*T6+U6*V6+W6*X6+Y6*Z6 -> 0 | AB6: =D6+F6+H6+J6+L6+N6+P6+R6+T6+V6+X6+Z6 -> 0
A7: 4 | B7: Kukuruz | C7: =W7 -> 204.9744 | E7: =W7 -> 204.9744 | G7: =W7 -> 204.9744 | I7: =W7+Usevi!F115+Usevi!F116+Usevi!F117+Usevi!F118+Usevi!F119+Usevi!F120+Usevi!F121+Usevi!F122+Usevi!F123+Usevi!F124 -> 325.4798 | K7: =Usevi!F107+Usevi!F108+Usevi!F109+Usevi!F110+Usevi!F111+Usevi!F112+Usevi!F113+Usevi!F114+Usevi!F115+Usevi!F116+Usevi!F117+Usevi!F118+Usevi!F119+Usevi!F120+Usevi!F121+Usevi!F122+Usevi!F123+Usevi!F124+Usevi!F125+Usevi!F126+Usevi!F127 -> 394.1784 | M7: =K7+Usevi!F128 -> 397.5732 | O7: =M7 -> 397.5732 | Q7: =O7 -> 397.5732 | S7: =Q7 -> 397.5732 | U7: =Usevi!F107+Usevi!F108+Usevi!F109+Usevi!F110 -> 70.2822 | W7: =U7+Usevi!F111+Usevi!F112+Usevi!F113+Usevi!F114 -> 204.9744 | Y7: =W7 -> 204.9744 | AA7: =C7*D7+E7*F7+G7*H7+I7*J7+K7*L7+M7*N7+O7*P7+Q7*R7+S7*T7+U7*V7+W7*X7+Y7*Z7 -> 0 | AB7: =D7+F7+H7+J7+L7+N7+P7+R7+T7+V7+X7+Z7 -> 0
A8: 5 | B8: Silažni kukuruz | C8: =Y8 -> 204.9744 | E8: =C8 -> 204.9744 | G8: =E8 -> 204.9744 | I8: =G8+Usevi!F150+Usevi!F151+Usevi!F152+Usevi!F153+Usevi!F154+Usevi!F155+Usevi!F156+Usevi!F157+Usevi!F158+Usevi!F159 -> 325.4798 | K8: =Usevi!F142+Usevi!F143+Usevi!F144+Usevi!F145+Usevi!F146+Usevi!F147+Usevi!F148+Usevi!F149+Usevi!F150+Usevi!F151+Usevi!F152+Usevi!F153+Usevi!F154+Usevi!F155+Usevi!F156+Usevi!F157+Usevi!F158+Usevi!F159+Usevi!F160+Usevi!F161+Usevi!F162 -> 394.1784 | M8: =K8+Usevi!F163 -> 397.5732 | O8: =M8 -> 397.5732 | Q8: =O8 -> 397.5732 | S8: =Usevi!F142+Usevi!F143+Usevi!F144+Usevi!F145 -> 70.2822 | U8: =S8 -> 70.2822 | W8: =U8+Usevi!F146+Usevi!F147+Usevi!F148+Usevi!F149 -> 204.9744 | Y8: =W8 -> 204.9744 | AA8: =C8*D8+E8*F8+G8*H8+I8*J8+K8*L8+M8*N8+O8*P8+Q8*R8+S8*T8+U8*V8+W8*X8+Y8*Z8 -> 0 | AB8: =D8+F8+H8+J8+L8+N8+P8+R8+T8+V8+X8+Z8 -> 0
A9: 6 | B9: Suncokret | C9: =Y9 -> 99.1756 | E9: =C9 -> 99.1756 | G9: =E9 -> 99.1756 | I9: =G9+Usevi!F183+Usevi!F184+Usevi!F185+Usevi!F186+Usevi!F187/2+Usevi!F188/2 -> 197.941 | K9: =I9+Usevi!F193+Usevi!F194+Usevi!F195 -> 254.492 | M9: =K9+Usevi!F187/2+Usevi!F188/2+Usevi!F196 -> 260.1992 | O9: =M9 -> 260.1992 | Q9: =O9 -> 260.1992 | S9: 0 | U9: 0 | W9: =Usevi!F179+Usevi!F180+Usevi!F181+Usevi!F182 -> 99.1756 | Y9: =W9 -> 99.1756 | AA9: =C9*D9+E9*F9+G9*H9+I9*J9+K9*L9+M9*N9+O9*P9+Q9*R9+S9*T9+U9*V9+W9*X9+Y9*Z9 -> 0 | AB9: =D9+F9+H9+J9+L9+N9+P9+R9+T9+V9+X9+Z9 -> 0
A10: 7 | B10: Šećerna repa | C10: =Y10 -> 271.0076 | E10: =C10 -> 271.0076 | G10: =E10+Usevi!F218+Usevi!F219+Usevi!F220+Usevi!F221+Usevi!F222+Usevi!F223 -> 539.1631 | I10: =G10+Usevi!F224/6+Usevi!F225/6+Usevi!F226/2 -> 589.4755 | K10: =I10+Usevi!F224/6+Usevi!F225/6+Usevi!F226/2+Usevi!F232+Usevi!F233 -> 643.7239 | M10: =K10+Usevi!F224/6*2+Usevi!F225/6*2+Usevi!F228 -> 677.4887 | O10: =M10+Usevi!F224/6+Usevi!F225/6+Usevi!F227 -> 714.2411 | Q10: =O10+Usevi!F224/6+Usevi!F225/6+Usevi!F229 -> 735.1955 | S10: =Q10 -> 735.1955 | U10: =Usevi!F210+Usevi!F211+Usevi!F212+Usevi!F213 -> 70.2822 | W10: ='Zalihe na parceli'!U10+Usevi!F214+Usevi!F215+Usevi!F216+Usevi!F217 -> 271.0076 | Y10: =W10 -> 271.0076 | AA10: =C10*D10+E10*F10+G10*H10+I10*J10+K10*L10+M10*N10+O10*P10+Q10*R10+S10*T10+U10*V10+W10*X10+Y10*Z10 -> 0 | AB10: =D10+F10+H10+J10+L10+N10+P10+R10+T10+V10+X10+Z10 -> 0
A11: 8 | B11: Soja | C11: =Y11 -> 123.596 | E11: =C11 -> 123.596 | G11: =E11 -> 123.596 | I11: =G11+Usevi!F253+Usevi!F254+Usevi!F255+Usevi!F256+Usevi!F257+Usevi!F258+Usevi!F259+Usevi!F260+Usevi!F261+Usevi!F262+Usevi!F263 -> 319.643 | K11: =I11+Usevi!F264 -> 321.611 | M11: =K11+Usevi!F265+Usevi!F266+Usevi!F267+Usevi!F268+Usevi!F269+Usevi!F270+Usevi!F271+Usevi!F272+Usevi!F273 -> 376.5727 | O11: =M11 -> 376.5727 | Q11: =O11 -> 376.5727 | S11: =Q11 -> 376.5727 | U11: =Usevi!F247+Usevi!F248 -> 26.4204 | W11: =U11+Usevi!F249+Usevi!F250+Usevi!F251+Usevi!F252 -> 123.596 | Y11: =W11 -> 123.596 | AA11: =C11*D11+E11*F11+G11*H11+I11*J11+K11*L11+M11*N11+O11*P11+Q11*R11+S11*T11+U11*V11+W11*X11+Y11*Z11 -> 0 | AB11: =D11+F11+H11+J11+L11+N11+P11+R11+T11+V11+X11+Z11 -> 0
A12: 9 | B12: Stočni grašak | C12: =Y12 -> 313.3754 | E12: =C12 -> 313.3754 | G12: =E12 -> 313.3754 | I12: =G12 -> 313.3754 | K12: =I12 -> 313.3754 | M12: =K12 -> 313.3754 | O12: 0 | Q12: 0 | S12: 0 | U12: =Usevi!F287+Usevi!F288+Usevi!F289+Usevi!F290+Usevi!F291+Usevi!F292+Usevi!F293+Usevi!F294+Usevi!F295+Usevi!F296+Usevi!F297+Usevi!F298+Usevi!F299+Usevi!F300+Usevi!F301 -> 313.3754 | W12: =U12 -> 313.3754 | Y12: =W12 -> 313.3754 | AA12: =C12*D12+E12*F12+G12*H12+I12*J12+K12*L12+M12*N12+O12*P12+Q12*R12+S12*T12+U12*V12+W12*X12+Y12*Z12 -> 0 | AB12: =D12+F12+H12+J12+L12+N12+P12+R12+T12+V12+X12+Z12 -> 0
A13: 10 | B13: Lucerka | C13: =Y13 -> 65.4877 | E13: =C13 -> 65.4877 | G13: =E13+Usevi!F325+Usevi!F326+Usevi!F327+Usevi!F328+Usevi!F329+Usevi!F330+Usevi!F331 -> 89.255 | I13: =G13 -> 89.255 | K13: =I13 -> 89.255 | M13: =K13 -> 89.255 | O13: =M13 -> 89.255 | Q13: =O13 -> 89.255 | S13: =Q13 -> 89.255 | U13: =Usevi!F316+Usevi!F317+Usevi!F318+Usevi!F319+Usevi!F320+Usevi!F321+Usevi!F322+Usevi!F323+Usevi!F324 -> 65.4877 | W13: =U13 -> 65.4877 | Y13: =W13 -> 65.4877 | AA13: =C13*D13+E13*F13+G13*H13+I13*J13+K13*L13+M13*N13+O13*P13+Q13*R13+S13*T13+U13*V13+W13*X13+Y13*Z13 -> 0 | AB13: =D13+F13+H13+J13+L13+N13+P13+R13+T13+V13+X13+Z13 -> 0
A14: 11 | B14: Raž | C14: =Y14 -> 213.6146 | E14: =C14+Usevi!F360+Usevi!F361+Usevi!F362 -> 268.0746 | G14: =E14 -> 268.0746 | I14: =G14 -> 268.0746 | K14: ='Zalihe na parceli'!I14+Usevi!F363+Usevi!F364+Usevi!F365+Usevi!F366+Usevi!F367+Usevi!F368 -> 311.5974 | M14: =K14 -> 311.5974 | O14: 0 | Q14: 0 | S14: 0 | U14: =Usevi!F351+Usevi!F352+Usevi!F353+Usevi!F354+Usevi!F355+Usevi!F356+Usevi!F357+Usevi!F358+Usevi!F359 -> 213.6146 | W14: =U14 -> 213.6146 | Y14: =W14 -> 213.6146 | AA14: =C14*D14+E14*F14+G14*H14+I14*J14+K14*L14+M14*N14+O14*P14+Q14*R14+S14*T14+U14*V14+W14*X14+Y14*Z14 -> 0 | AB14: =D14+F14+H14+J14+L14+N14+P14+R14+T14+V14+X14+Z14 -> 0
A15: 12 | B15: Ovas | C15: =Y15 -> 213.6146 | E15: =C15+Usevi!F393+Usevi!F394+Usevi!F395 -> 268.0746 | G15: =E15 -> 268.0746 | I15: =G15 -> 268.0746 | K15: =I15+Usevi!F396+Usevi!F397+Usevi!F398+Usevi!F399+Usevi!F400+Usevi!F401 -> 311.5974 | M15: =K15 -> 311.5974 | O15: 0 | Q15: 0 | S15: 0 | U15: =Usevi!F384+Usevi!F385+Usevi!F386+Usevi!F387+Usevi!F388+Usevi!F389+Usevi!F390+Usevi!F391+Usevi!F392 -> 213.6146 | W15: =U15 -> 213.6146 | Y15: =W15 -> 213.6146 | AA15: =C15*D15+E15*F15+G15*H15+I15*J15+K15*L15+M15*N15+O15*P15+Q15*R15+S15*T15+U15*V15+W15*X15+Y15*Z15 -> 0 | AB15: =D15+F15+H15+J15+L15+N15+P15+R15+T15+V15+X15+Z15 -> 0
A16: 13 | B16: Uljana repica | C16: =Y16 -> 213.6206 | E16: =C16+Usevi!F429+Usevi!F430+Usevi!F431 -> 268.0806 | G16: =E16 -> 268.0806 | I16: =G16 -> 268.0806 | K16: =I16 -> 268.0806 | M16: =K16 -> 268.0806 | O16: =Usevi!F417+Usevi!F418+Usevi!F419+Usevi!F420+Usevi!F425/2+Usevi!F426/2+Usevi!F427 -> 149.1996 | Q16: =O16+Usevi!F421+Usevi!F422+Usevi!F423+Usevi!F424 -> 203.4362 | S16: =Q16 -> 203.4362 | U16: =S16+Usevi!F425/2+Usevi!F426/2+Usevi!F428 -> 213.6206 | W16: =U16 -> 213.6206 | Y16: =W16 -> 213.6206 | AA16: =C16*D16+E16*F16+G16*H16+I16*J16+K16*L16+M16*N16+O16*P16+Q16*R16+S16*T16+U16*V16+W16*X16+Y16*Z16 -> 0 | AB16: =D16+F16+H16+J16+L16+N16+P16+R16+T16+V16+X16+Z16 -> 0
A17: 14 | B17: Duvan | C17: =Y17 -> 214.6788 | E17: =C17 -> 214.6788 | G17: =E17 -> 214.6788 | I17: =G17+Usevi!F454+Usevi!F455+Usevi!F456+Usevi!F457+Usevi!F458+Usevi!F459 -> 317.9914 | K17: =I17+Usevi!F451+Usevi!F452+Usevi!F453+Usevi!F460+Usevi!F461+Usevi!F462+Usevi!F463+Usevi!F464+Usevi!F465+Usevi!F466 -> 421.99494 | M17: =K17+Usevi!F467+Usevi!F468+Usevi!F469/2+Usevi!F470/2+Usevi!F471+Usevi!F474/2 -> 557.93454 | O17: =M17+Usevi!F469/2+Usevi!F470/2+Usevi!F472+Usevi!F473+Usevi!F474/2 -> 635.68694 | Q17: =O17 -> 635.68694 | S17: =Q17 -> 635.68694 | U17: 0 | W17: =Usevi!F445+Usevi!F446+Usevi!F447+Usevi!F448+Usevi!F449+Usevi!F450 -> 214.6788 | Y17: =W17 -> 214.6788 | AA17: =C17*D17+E17*F17+G17*H17+I17*J17+K17*L17+M17*N17+O17*P17+Q17*R17+S17*T17+U17*V17+W17*X17+Y17*Z17 -> 0 | AB17: =D17+F17+H17+J17+L17+N17+P17+R17+T17+V17+X17+Z17 -> 0
A18: 15 | B18: Heljda | C18: =Y18 -> 87.18 | E18: =C18 -> 87.18 | G18: =E18+Usevi!F493+Usevi!F494+Usevi!F495+Usevi!F496 -> 902.1768 | I18: =G18 -> 902.1768 | K18: =I18 -> 902.1768 | M18: =K18 -> 902.1768 | O18: =M18 -> 902.1768 | Q18: 0 | S18: 0 | U18: =Usevi!F490+Usevi!F491 -> 59.02 | W18: =U18+Usevi!F492 -> 87.18 | Y18: =W18 -> 87.18 | AA18: =C18*D18+E18*F18+G18*H18+I18*J18+K18*L18+M18*N18+O18*P18+Q18*R18+S18*T18+U18*V18+W18*X18+Y18*Z18 -> 0 | AB18: =D18+F18+H18+J18+L18+N18+P18+R18+T18+V18+X18+Z18 -> 0
A19: 16 | B19: Krompir | C19: =Y19 -> 314.8694 | E19: =C19 -> 314.8694 | G19: =E19+Povrće!F13+Povrće!F14+Povrće!F15+Povrće!F16+Povrće!F17+Povrće!F18+Povrće!F19+Povrće!F20 -> 1994.8597 | I19: =G19 -> 1994.8597 | K19: =I19+Povrće!F21+Povrće!F22+Povrće!F23+Povrće!F24/4+Povrće!F25/4+Povrće!F26+Povrće!F27 -> 2160.2047 | M19: =K19+Povrće!F24/4+Povrće!F25/4+Povrće!F28+Povrće!F29+Povrće!F33/2+Povrće!F34 -> 2315.9827 | O19: =M19+Povrće!F24/4+Povrće!F25/4+Povrće!F30+Povrće!F31+Povrće!F33/2 -> 2468.1691 | Q19: =O19 -> 2468.1691 | S19: =Povrće!F5+Povrće!F6+Povrće!F7+Povrće!F8 -> 114.144 | U19: =S19 -> 114.144 | W19: =U19+Povrće!F9+Povrće!F10+Povrće!F11+Povrće!F12 -> 314.8694 | Y19: =W19 -> 314.8694 | AA19: =C19*D19+E19*F19+G19*H19+I19*J19+K19*L19+M19*N19+O19*P19+Q19*R19+S19*T19+U19*V19+W19*X19+Y19*Z19 -> 0 | AB19: =D19+F19+H19+J19+L19+N19+P19+R19+T19+V19+X19+Z19 -> 0
A20: 17 | B20: Pasulj | C20: =Y20 -> 123.596 | E20: =C20 -> 123.596 | G20: =E20 -> 123.596 | I20: =G20+Povrće!F54+Povrće!F55+Povrće!F56+Povrće!F57+Povrće!F58+Povrće!F59+Povrće!F60+Povrće!F61+Povrće!F62+Povrće!F63+Povrće!F64 -> 1029.849 | K20: =I20+Povrće!F65+Povrće!F66+Povrće!F67+Povrće!F68 -> 1066.1094 | M20: =K20+Povrće!F69+Povrće!F70+Povrće!F71+Povrće!F72+Povrće!F73+Povrće!F74+Povrće!F75 -> 1120.7462 | O20: 0 | Q20: =Povrće!F48 -> 21.6234 | S20: =Q20+Povrće!F49 -> 26.4204 | U20: =S20 -> 26.4204 | W20: =U20+Povrće!F50+Povrće!F51+Povrće!F52+Povrće!F53 -> 123.596 | Y20: =W20 -> 123.596 | AA20: =C20*D20+E20*F20+G20*H20+I20*J20+K20*L20+M20*N20+O20*P20+Q20*R20+S20*T20+U20*V20+W20*X20+Y20*Z20 -> 0 | AB20: =D20+F20+H20+J20+L20+N20+P20+R20+T20+V20+X20+Z20 -> 0
A21: 18 | B21: Rotkvica | C21: =Y21 -> 287.5634 | E21: =C21 -> 287.5634 | G21: =E21+Povrće!F95+Povrće!F96+Povrće!F97+Povrće!F98 -> 356.8278 | I21: =G21+Povrće!F99+Povrće!F100+Povrće!F106/2 -> 1204.4023 | K21: =I21+Povrće!F101+Povrće!F102+Povrće!F103+Povrće!F104+Povrće!F105+Povrće!F106/2 -> 1290.5371 | M21: 0 | O21: 0 | Q21: 0 | S21: 0 | U21: =Povrće!F89+Povrće!F90+Povrće!F91+Povrće!F92+Povrće!F93+Povrće!F94 -> 287.5634 | W21: =U21 -> 287.5634 | Y21: =W21 -> 287.5634 | AA21: =C21*D21+E21*F21+G21*H21+I21*J21+K21*L21+M21*N21+O21*P21+Q21*R21+S21*T21+U21*V21+W21*X21+Y21*Z21 -> 0 | AB21: =D21+F21+H21+J21+L21+N21+P21+R21+T21+V21+X21+Z21 -> 0
A22: 19 | B22: Grašak | C22: =Y22 -> 199.8398 | E22: =C22 -> 199.8398 | G22: =E22+Povrće!F124+Povrće!F125+Povrće!F126+Povrće!F127+Povrće!F128+Povrće!F129+Povrće!F130+Povrće!F131/3+Povrće!F132/3+Povrće!F133 -> 952.9752 | I22: =G22+Povrće!F131/3*2+Povrće!F132/3*2+Povrće!F134+Povrće!F135+Povrće!F137/2 -> 1046.7135 | K22: =I22+Povrće!F136/2+Povrće!F137/2 -> 1099.3575 | M22: 0 | O22: 0 | Q22: 0 | S22: 0 | U22: =Povrće!F120+Povrće!F121+Povrće!F122+Povrće!F123 -> 199.8398 | W22: =U22 -> 199.8398 | Y22: =W22 -> 199.8398 | AA22: =C22*D22+E22*F22+G22*H22+I22*J22+K22*L22+M22*N22+O22*P22+Q22*R22+S22*T22+U22*V22+W22*X22+Y22*Z22 -> 0 | AB22: =D22+F22+H22+J22+L22+N22+P22+R22+T22+V22+X22+Z22 -> 0
A23: 20 | B23: Boranija | C23: =Y23 -> 123.596 | E23: =C23 -> 123.596 | G23: =E23 -> 123.596 | I23: =G23+Povrće!F157+Povrće!F158+Povrće!F159+Povrće!F160+Povrće!F161+Povrće!F162+Povrće!F163+Povrće!F164+Povrće!F165+Povrće!F166 -> 1371.982 | K23: =I23+Povrće!F167+Povrće!F168+Povrće!F169+Povrće!F170 -> 1456.2616 | M23: =K23+Povrće!F171+Povrće!F172+Povrće!F173+Povrće!F174+Povrće!F175 -> 1516.4948 | O23: =Povrće!F151 -> 21.6234 | Q23: =O23 -> 21.6234 | S23: =Q23+Povrće!F152 -> 26.4204 | U23: =S23 -> 26.4204 | W23: =U23+Povrće!F153+Povrće!F154+Povrće!F155+Povrće!F156 -> 123.596 | Y23: =W23 -> 123.596 | AA23: =C23*D23+E23*F23+G23*H23+I23*J23+K23*L23+M23*N23+O23*P23+Q23*R23+S23*T23+U23*V23+W23*X23+Y23*Z23 -> 0 | AB23: =D23+F23+H23+J23+L23+N23+P23+R23+T23+V23+X23+Z23 -> 0
A24: 21 | B24: Crni luk | C24: =Y24 -> 313.8362 | E24: =C24 -> 313.8362 | G24: =E24+Povrće!F198+Povrće!F199+Povrće!F200+Povrće!F201+Povrće!F202+Povrće!F203 -> 1367.012 | I24: =G24+Povrće!F204/2+Povrće!F205/2+Povrće!F206+Povrće!F207 -> 1494.1092 | K24: =I24+Povrće!F204/2+Povrće!F205/2+Povrće!F208+Povrće!F209+Povrće!F210/2+Povrće!F211 -> 1688.6012 | M24: =K24+Povrće!F210/2 -> 1691.996 | O24: =Povrće!F190+Povrće!F191+Povrće!F192 -> 109.347 | Q24: =O24 -> 109.347 | S24: =Q24+Povrće!F193 -> 114.144 | U24: =S24 -> 114.144 | W24: =U24+Povrće!F194+Povrće!F195+Povrće!F196+Povrće!F197 -> 313.8362 | Y24: =W24 -> 313.8362 | AA24: =C24*D24+E24*F24+G24*H24+I24*J24+K24*L24+M24*N24+O24*P24+Q24*R24+S24*T24+U24*V24+W24*X24+Y24*Z24 -> 0 | AB24: =D24+F24+H24+J24+L24+N24+P24+R24+T24+V24+X24+Z24 -> 0
A25: 22 | B25: Paprika | C25: =Y25 -> 862.8624 | E25: =C25+Povrće!F234+Povrće!F236+Povrće!F237 -> 1094.6308 | G25: =E25 -> 1094.6308 | I25: =G25+Povrće!F238+Povrće!F239+Povrće!F240+Povrće!F241+Povrće!F242+Povrće!F243 -> 1207.8034 | K25: =I25+Povrće!F244+Povrće!F245+Povrće!F246+Povrće!F247+Povrće!F248+Povrće!F249 -> 1320.9826 | M25: =K25+Povrće!F250+Povrće!F251+Povrće!F252+Povrće!F253+Povrće!F254/4 -> 1504.9414 | O25: =Povrće!F226+Povrće!F254/4+Povrće!F255/4+Povrće!F258+Povrće!F259 -> 169.749 | Q25: =O25+Povrće!F227+Povrće!F228+Povrće!F229+Povrće!F254/4+Povrće!F255/4+Povrće!F256+Povrće!F257 -> 473.4548 | S25: =Q25+Povrće!F254/4+Povrće!F255/4+Povrće!F260+Povrće!F261 -> 621.0304 | U25: =S25+Povrće!F255/4+Povrće!F262 -> 662.137 | W25: =U25+Povrće!F230+Povrće!F231+Povrće!F232+Povrće!F233 -> 862.8624 | Y25: =W25 -> 862.8624 | AA25: =C25*D25+E25*F25+G25*H25+I25*J25+K25*L25+M25*N25+O25*P25+Q25*R25+S25*T25+U25*V25+W25*X25+Y25*Z25 -> 0 | AB25: =D25+F25+H25+J25+L25+N25+P25+R25+T25+V25+X25+Z25 -> 0
A26: 23 | B26: Krastavac | C26: =Y26 -> 313.8362 | E26: =C26 -> 313.8362 | G26: =E26 -> 313.8362 | I26: =G26+Povrće!F284+Povrće!F285+Povrće!F286+Povrće!F287+Povrće!F288+Povrće!F289+Povrće!F290/3+Povrće!F291 -> 1011.1788 | K26: =I26+Povrće!F290/3+Povrće!F292+Povrće!F293+Povrće!F294+Povrće!F298/2+Povrće!F299/2 -> 1183.2732 | M26: =K26+Povrće!F290/3+Povrće!F295+Povrće!F296+Povrće!F297+Povrće!F298/2+Povrće!F299/2 -> 1353.5452 | O26: =Povrće!F276+Povrće!F277+Povrće!F278 -> 109.347 | Q26: =O26 -> 109.347 | S26: =Q26+Povrće!F279 -> 114.144 | U26: =S26 -> 114.144 | W26: =U26+Povrće!F280+Povrće!F281+Povrće!F282+Povrće!F283 -> 313.8362 | Y26: =W26 -> 313.8362 | AA26: =C26*D26+E26*F26+G26*H26+I26*J26+K26*L26+M26*N26+O26*P26+Q26*R26+S26*T26+U26*V26+W26*X26+Y26*Z26 -> 0 | AB26: =D26+F26+H26+J26+L26+N26+P26+R26+T26+V26+X26+Z26 -> 0
A27: 24 | B27: Cvekla crvena | C27: =Y27 -> 369.4286 | E27: =C27 -> 369.4286 | G27: =E27 -> 369.4286 | I27: =G27+Povrće!F321+Povrće!F322+Povrće!F323 -> 468.5528 | K27: =I27+Povrće!F324+Povrće!F325+Povrće!F326+Povrće!F327/3+Povrće!F328/3+Povrće!F329+Povrće!F332/2+Povrće!F333/2 -> 884.9713 | M27: =K27+Povrće!F327/3+Povrće!F328/3+Povrće!F330+Povrće!F332/2+Povrće!F333/2 -> 974.0335 | O27: =Povrće!F313+Povrće!F314+Povrće!F315+Povrće!F327/3+Povrće!F328/3+Povrće!F331 -> 164.9394 | Q27: =O27 -> 164.9394 | S27: =Q27+Povrće!F316 -> 169.7364 | U27: =S27 -> 169.7364 | W27: =U27+Povrće!F317+Povrće!F318+Povrće!F319+Povrće!F320 -> 369.4286 | Y27: =W27 -> 369.4286 | AA27: =C27*D27+E27*F27+G27*H27+I27*J27+K27*L27+M27*N27+O27*P27+Q27*R27+S27*T27+U27*V27+W27*X27+Y27*Z27 -> 0 | AB27: =D27+F27+H27+J27+L27+N27+P27+R27+T27+V27+X27+Z27 -> 0
A28: 25 | B28: Paradajz | C28: =Y28 -> 313.8362 | E28: =C28+Povrće!F355+Povrće!F356+Povrće!F357+Povrće!F358 -> 614.00414 | G28: =E28 -> 614.00414 | I28: =G28+Povrće!F359+Povrće!F360+Povrće!F361+Povrće!F362 -> 715.78514 | K28: =I28+Povrće!F363+Povrće!F364+Povrće!F365+Povrće!F366+Povrće!F367+Povrće!F368+Povrće!F369 -> 828.96434 | M28: =K28+Povrće!F370+Povrće!F371/2+Povrće!F372+Povrće!F373+Povrće!F376+Povrće!F377+Povrće!F378/2 -> 1104.0247 | O28: =M28+Povrće!F371/2+Povrće!F374+Povrće!F375+Povrće!F378/2 -> 1323.1679 | Q28: =Povrće!F347+Povrće!F348+Povrće!F349 -> 109.347 | S28: =Q28+Povrće!F350 -> 114.144 | U28: =S28 -> 114.144 | W28: =U28+Povrće!F351+Povrće!F352+Povrće!F353+Povrće!F354 -> 313.8362 | Y28: =W28 -> 313.8362 | AA28: =C28*D28+E28*F28+G28*H28+I28*J28+K28*L28+M28*N28+O28*P28+Q28*R28+S28*T28+U28*V28+W28*X28+Y28*Z28 -> 0 | AB28: =D28+F28+H28+J28+L28+N28+P28+R28+T28+V28+X28+Z28 -> 0
A29: 26 | B29: Spanać | C29: =Y29 -> 137.4966 | E29: =C29 -> 137.4966 | G29: =E29+Povrće!F397+Povrće!F398+Povrće!F399+Povrće!F400+Povrće!F401+Povrće!F402+Povrće!F403+Povrće!F404+Povrće!F405 -> 535.3342 | I29: =G29 -> 535.3342 | K29: 0 | M29: 0 | O29: 0 | Q29: 0 | S29: 0 | U29: =Povrće!F392+Povrće!F393+Povrće!F394+Povrće!F395+Povrće!F396 -> 137.4966 | W29: =U29 -> 137.4966 | Y29: =W29 -> 137.4966 | AA29: =C29*D29+E29*F29+G29*H29+I29*J29+K29*L29+M29*N29+O29*P29+Q29*R29+S29*T29+U29*V29+W29*X29+Y29*Z29 -> 0 | AB29: =D29+F29+H29+J29+L29+N29+P29+R29+T29+V29+X29+Z29 -> 0
A30: 27 | B30: Lubenica | C30: =Y30 -> 378.239 | E30: =C30 -> 378.239 | G30: =E30+Povrće!F427 -> 573.239 | I30: =G30+Povrće!F428+Povrće!F429+Povrće!F430+Povrće!F431+Povrće!F432+Povrće!F433 -> 690.1316 | K30: =I30+Povrće!F434+Povrće!F435+Povrće!F436+Povrće!F437+Povrće!F438+Povrće!F439/4+Povrće!F440 -> 822.9308 | M30: =K30+Povrće!F439/2+Povrće!F441+Povrće!F442+Povrće!F444+Povrće!F445 -> 942.1132 | O30: =M30+Povrće!F439/4+Povrće!F443+Povrće!F446 -> 1024.4248 | Q30: =Povrće!F419+Povrće!F420+Povrće!F421+Povrće!F422 -> 177.5136 | S30: =Q30 -> 177.5136 | U30: =S30 -> 177.5136 | W30: =U30+Povrće!F423+Povrće!F424+Povrće!F425+Povrće!F426 -> 378.239 | Y30: =W30 -> 378.239 | AA30: =C30*D30+E30*F30+G30*H30+I30*J30+K30*L30+M30*N30+O30*P30+Q30*R30+S30*T30+U30*V30+W30*X30+Y30*Z30 -> 0 | AB30: =D30+F30+H30+J30+L30+N30+P30+R30+T30+V30+X30+Z30 -> 0
A31: 28 | B31: Karfiol | C31: =Y31 -> 137.4966 | E31: =C31 -> 137.4966 | G31: =E31+Povrće!F465 -> 587.4966 | I31: =G31+Povrće!F466+Povrće!F467+Povrće!F468 -> 653.9566 | K31: =I31+Povrće!F469+Povrće!F470+Povrće!F471+Povrće!F472+Povrće!F473+Povrće!F474+Povrće!F475+Povrće!F476/5*3+Povrće!F477 -> 813.1279 | M31: =K31+Povrće!F476/5+Povrće!F478+Povrće!F480+Povrće!F481 -> 882.8567 | O31: =M31+Povrće!F476/5+Povrće!F479+Povrće!F482/2 -> 965.1683 | Q31: =O31+Povrće!F482/2 -> 1014.3683 | S31: 0 | U31: =Povrće!F460+Povrće!F461+Povrće!F462+Povrće!F463+Povrće!F464 -> 137.4966 | W31: =U31 -> 137.4966 | Y31: =W31 -> 137.4966 | AA31: =C31*D31+E31*F31+G31*H31+I31*J31+K31*L31+M31*N31+O31*P31+Q31*R31+S31*T31+U31*V31+W31*X31+Y31*Z31 -> 0 | AB31: =D31+F31+H31+J31+L31+N31+P31+R31+T31+V31+X31+Z31 -> 0
A32: 29 | B32: Kupus | C32: =Y32 -> 137.4966 | E32: =C32 -> 137.4966 | G32: =E32+Povrće!F501 -> 787.7216 | I32: =G32+Povrće!F502+Povrće!F503+Povrće!F504 -> 854.1816 | K32: =I32+Povrće!F505+Povrće!F506+Povrće!F507+Povrće!F508+Povrće!F509+Povrće!F510+Povrće!F511+Povrće!F512/5*2+Povrće!F513/3*2 -> 1004.2878 | M32: =K32+Povrće!F512/5+Povrće!F513/3+Povrće!F516+Povrće!F517 -> 1065.8001 | O32: =M32+Povrće!F512/5+Povrće!F514+Povrće!F518/2 -> 1132.2817 | Q32: =O32+Povrće!F512/5+Povrće!F515+Povrće!F518/2 -> 1214.5933 | S32: 0 | U32: =Povrće!F496+Povrće!F497+Povrće!F498+Povrće!F499+Povrće!F500 -> 137.4966 | W32: =U32 -> 137.4966 | Y32: =W32 -> 137.4966 | AA32: =C32*D32+E32*F32+G32*H32+I32*J32+K32*L32+M32*N32+O32*P32+Q32*R32+S32*T32+U32*V32+W32*X32+Y32*Z32 -> 0 | AB32: =D32+F32+H32+J32+L32+N32+P32+R32+T32+V32+X32+Z32 -> 0
A33: 30 | B33: Kupus postrni | C33: 0 | E33: 0 | G33: 0 | I33: 0 | K33: 0 | M33: 0 | O33: =Povrće!F532+Povrće!F533+Povrće!F534+Povrće!F535+Povrće!F536+Povrće!F537+Povrće!F538+Povrće!F539+Povrće!F540+Povrće!F541+Povrće!F542++Povrće!F543+Povrće!F544+Povrće!F545/5*2+Povrće!F546/3*2 -> 945.585 | Q33: =O33+Povrće!F545/5*3+Povrće!F546/3+Povrće!F547+Povrće!F548+Povrće!F549+Povrće!F550/2 -> 1057.4905 | S33: =Q33+Povrće!F550/2 -> 1106.6905 | U33: 0 | W33: 0 | Y33: 0 | AA33: =C33*D33+E33*F33+G33*H33+I33*J33+K33*L33+M33*N33+O33*P33+Q33*R33+S33*T33+U33*V33+W33*X33+Y33*Z33 -> 0 | AB33: =D33+F33+H33+J33+L33+N33+P33+R33+T33+V33+X33+Z33 -> 0
A34: 31 | B34: Salata | C34: =Y34 -> 137.4966 | E34: =C34+Povrće!F569 -> 937.4966 | G34: =E34+Povrće!F570+Povrće!F571+Povrće!F572+Povrće!F573+Povrće!F574+Povrće!F575+Povrće!F576+Povrće!F577/2 -> 1092.7134 | I34: =G34+Povrće!F577/2+Povrće!F578+Povrće!F579/2+Povrće!F580 -> 1162.4422 | K34: =I34+Povrće!F579/2+Povrće!F581 -> 1266.9238 | M34: 0 | O34: 0 | Q34: 0 | S34: 0 | U34: =Povrće!F564+Povrće!F565+Povrće!F566+Povrće!F567+Povrće!F568 -> 137.4966 | W34: =U34 -> 137.4966 | Y34: =W34 -> 137.4966 | AA34: =C34*D34+E34*F34+G34*H34+I34*J34+K34*L34+M34*N34+O34*P34+Q34*R34+S34*T34+U34*V34+W34*X34+Y34*Z34 -> 0 | AB34: =D34+F34+H34+J34+L34+N34+P34+R34+T34+V34+X34+Z34 -> 0
A35: 32 | B35: Šargarepa | C35: =Y35 -> 378.239 | E35: =C35 -> 378.239 | G35: =E35+Povrće!F603+Povrće!F604+Povrće!F605+Povrće!F606+Povrće!F607+Povrće!F608+Povrće!F609+Povrće!F610 -> 792.2561 | I35: =G35 -> 792.2561 | K35: =I35+Povrće!F611+Povrće!F612+Povrće!F613+Povrće!F614+Povrće!F615 -> 905.3915 | M35: =K35+Povrće!F616 -> 908.6387 | O35: =M35 -> 908.6387 | Q35: =O35 -> 908.6387 | S35: =Q35 -> 908.6387 | U35: =Povrće!F595+Povrće!F596+Povrće!F597+Povrće!F598 -> 177.5136 | W35: =U35+Povrće!F599+Povrće!F600+Povrće!F601+Povrće!F602 -> 378.239 | Y35: =W35 -> 378.239 | AA35: =C35*D35+E35*F35+G35*H35+I35*J35+K35*L35+M35*N35+O35*P35+Q35*R35+S35*T35+U35*V35+W35*X35+Y35*Z35 -> 0 | AB35: =D35+F35+H35+J35+L35+N35+P35+R35+T35+V35+X35+Z35 -> 0
A36: 33 | B36: Peršun | C36: =Y36 -> 378.239 | E36: =C36 -> 378.239 | G36: =E36+Povrće!F638+Povrće!F639+Povrće!F640+Povrće!F641+Povrće!F642+Povrće!F643+Povrće!F644+Povrće!F645 -> 628.7261 | I36: =G36 -> 628.7261 | K36: =I36+Povrće!F646+Povrće!F647+Povrće!F648+Povrće!F649+Povrće!F650 -> 741.8615 | M36: =K36+Povrće!F651 -> 745.1087 | O36: =M36 -> 745.1087 | Q36: =O36+Povrće!F631+Povrće!F632+Povrće!F633 -> 900.9989 | S36: =Q36 -> 900.9989 | U36: =Povrće!F630+Povrće!F631+Povrće!F632+Povrće!F633 -> 177.5136 | W36: =U36+Povrće!F634+Povrće!F635+Povrće!F636+Povrće!F637 -> 378.239 | Y36: =W36 -> 378.239 | AA36: =C36*D36+E36*F36+G36*H36+I36*J36+K36*L36+M36*N36+O36*P36+Q36*R36+S36*T36+U36*V36+W36*X36+Y36*Z36 -> 0 | AB36: =D36+F36+H36+J36+L36+N36+P36+R36+T36+V36+X36+Z36 -> 0
A37: 34 | B37: Plavi patlidžan | C37: =Y37 -> 137.4966 | E37: =C37+Povrće!F670 -> 257.4966 | G37: =E37 -> 257.4966 | I37: =G37+Povrće!F671+Povrće!F672+Povrće!F673 -> 323.9566 | K37: =I37+Povrće!F674+Povrće!F675+Povrće!F676+Povrće!F677+Povrće!F678+Povrće!F679+Povrće!F680+Povrće!F681/5+Povrće!F682 -> 489.0442 | M37: =K37+Povrće!F681/5*2+Povrće!F683+Povrće!F686+Povrće!F687 -> 560.7916 | O37: =M37+Povrće!F681/5+Povrće!F684+Povrće!F688/5*2 -> 716.9232 | Q37: =O37+Povrće!F681/5+Povrće!F685+Povrće!F688/5*2 -> 832.6048 | S37: =Q37+Povrće!F688/5 -> 881.8048 | U37: =Povrće!F665+Povrće!F666+Povrće!F667+Povrće!F668+Povrće!F669 -> 137.4966 | W37: =U37 -> 137.4966 | Y37: =W37 -> 137.4966 | AA37: =C37*D37+E37*F37+G37*H37+I37*J37+K37*L37+M37*N37+O37*P37+Q37*R37+S37*T37+U37*V37+W37*X37+Y37*Z37 -> 0 | AB37: =D37+F37+H37+J37+L37+N37+P37+R37+T37+V37+X37+Z37 -> 0
A38: 35 | B38: Šljiva - ekstenzivan zasad | C38: 0 | E38: =Voće!F12/2+Voće!F13/2+Voće!F14+Voće!F15 -> 85.325 | G38: =E38+Voće!F5+Voće!F6+Voće!F7 -> 123.4086 | I38: =G38+Voće!F9+Voće!F10+Voće!F11+Voće!F12/2+Voće!F13/2+Voće!F17+Voće!F16 -> 185.5182 | K38: =I38 -> 185.5182 | M38: =K38+Voće!F8/2 -> 192.0126 | O38: =M38+Voće!F8/2 -> 198.507 | Q38: 0 | S38: 0 | U38: 0 | W38: 0 | Y38: 0 | AA38: =C38*D38+E38*F38+G38*H38+I38*J38+K38*L38+M38*N38+O38*P38+Q38*R38+S38*T38+U38*V38+W38*X38+Y38*Z38 -> 0 | AB38: =D38+F38+H38+J38+L38+N38+P38+R38+T38+V38+X38+Z38 -> 0
A39: 36 | B39: Šljiva - intenzivan zasad | C39: =Y39 -> 80.601 | E39: =C39+Voće!F38/7+Voće!F39/7+Voće!F40 -> 264.492 | G39: =E39+Voće!F31+Voće!F32+Voće!F33+Voće!F34/4+Voće!F38/7+Voće!F39/7+Voće!F41+Voće!F42 -> 482.5878 | I39: =G39+Voće!F34/4+Voće!F35+Voće!F36+Voće!F37+Voće!F38/7+Voće!F39/7+Voće!F43 -> 635.7946 | K39: =I39+Voće!F38/7+Voće!F39/7+Voće!F44+Voće!F45 -> 666.1456 | M39: =K39+Voće!F34/4+Voće!F38/7+Voće!F39/7+Voće!F46+Voće!F47 -> 732.8538 | O39: =M39+Voće!F34/4+Voće!F38/7+Voće!F39/7+Voće!F48+Voće!F49 -> 917.252 | Q39: 0 | S39: 0 | U39: =Voće!F38/7+Voće!F39/7+Voće!F50 -> 62.151 | W39: =U39+Voće!F30 -> 80.601 | Y39: =W39 -> 80.601 | AA39: =C39*D39+E39*F39+G39*H39+I39*J39+K39*L39+M39*N39+O39*P39+Q39*R39+S39*T39+U39*V39+W39*X39+Y39*Z39 -> 0 | AB39: =D39+F39+H39+J39+L39+N39+P39+R39+T39+V39+X39+Z39 -> 0
A40: 37 | B40: Jabuka ekstenzivan zasad | C40: 0 | E40: 0 | G40: =Voće!F63+Voće!F64+Voće!F65+Voće!F66+Voće!F67/4+Voće!F71/4+Voće!F72/4+Voće!F73 -> 188.6034 | I40: =G40+Voće!F67/4+Voće!F68+Voće!F69+Voće!F70 -> 246.6058 | K40: =I40+Voće!F71/4+Voće!F72/4+Voće!F74+Voće!F75 -> 271.2068 | M40: =K40+Voće!F67/4+Voće!F71/2+Voće!F72/2+Voće!F76+Voće!F77+Voće!F78+Voće!F79 -> 390.224 | O40: =M40+Voće!F67/4 -> 393.4712 | Q40: =O40 -> 393.4712 | S40: =Q40 -> 393.4712 | U40: 0 | W40: 0 | Y40: 0 | AA40: =C40*D40+E40*F40+G40*H40+I40*J40+K40*L40+M40*N40+O40*P40+Q40*R40+S40*T40+U40*V40+W40*X40+Y40*Z40 -> 0 | AB40: =D40+F40+H40+J40+L40+N40+P40+R40+T40+V40+X40+Z40 -> 0
...

Sheet Aromatično i lekovito bilje
B1: KOMORAČ | D1: Obradivo zemljište (ha): | F1: 0
A3: KLIJENT | E3: OPTIMALNO
A4: R. br. | B4: Tehnološke operacije i korišćeni materijal | C4: Operacija u mesecu | D4: Trošak po kg ili litru (EUR) | E4: Optimalna potrošnja kg ili l/ha | F4: Optimalni troškovi tehnoloških operacija/ha (EUR)
A5: 1 | B5: Zaoravanje strnjike (1/6) | C5: VII | D5: 1.23 | E5: 2.93 | F5: =E5*D5 -> 3.6039
A6: 2 | B6: Tanjiranje (1/6) | C6: IX | D6: 1.23 | E6: 0.65 | F6: =E6*D6 -> 0.7995
A7: 3 | B7: Transport đubriva | C7: XI | D7: 1.23 | E7: 1.32 | F7: =E7*D7 -> 1.6236
B8: NPK đubrivo 15:15:15 | D8: 0.35 | E8: 300 | F8: =E8*D8 -> 105
A9: 4 | B9: Rasipanje min. đ. - 1. god. (1/6) | C9: XI | D9: 1.23 | E9: 0.19 | F9: =E9*D9 -> 0.2337
B10: Međ. kultiv. sa đ. - od 2-6. god. (5/6) | C10: XI | D10: 1.23 | E10: 2.43 | F10: =E10*D10 -> 2.9889
A11: 5 | B11: Oranje (1/6) | C11: XI | D11: 1.23 | E11: 3.61 | F11: =E11*D11 -> 4.4403
A12: 6 | B12: Predsetvena priprema zemljišta (1/6) | C12: III-IV | D12: 1.23 | E12: 0.36 | F12: =E12*D12 -> 0.4428
B13: Seme (1/6) | D13: 0 | E13: 12 | F13: =E13*D13 -> 0
A14: 7 | B14: Setva (1/6) | C14: III-IV | D14: 1.23 | E14: 0.56 | F14: =E14*D14 -> 0.6888
A15: 8 | B15: Transport vode | C15: V | D15: 1.23 | E15: 0.96 | F15: =E15*D15 -> 1.1808
A16: 9 | B16: Zaštita insekticidima | C16: V | D16: 1.23 | E16: 0.92 | F16: =E16*D16 -> 1.1316
B17: Perfection | D17: 9.19 | E17: 1.2 | F17: =E17*D17 -> 11.028
A18: 10 | B18: Transport đubriva | C18: V | D18: 1.23 | E18: 0.9 | F18: =E18*D18 -> 1.107
B19: KAN 27% N | D19: 0.26 | E19: 200 | F19: =E19*D19 -> 52
A20: 11 | B20: I međuredno kultiviranje sa đubrenjem | C20: V | D20: 1.23 | E20: 2.92 | F20: =E20*D20 -> 3.5916
A21: 12 | B21: Žetva kombajnom | C21: IX-X | D21: 1.23 | E21: 8.33 | F21: =E21*D21 -> 10.2459
A22: 13 | B22: Transport komorača | C22: IX-X | D22: 1.23 | E22: 5.64 | F22: =E22*D22 -> 6.9372
A23: 14 | B23: Košenje | C23: X-XI | D23: 1.23 | E23: 2.5 | F23: =E23*D23 -> 3.075
A24: 15 | B24: Transport đubriva | C24: XI | D24: 1.23 | E24: 1.32 | F24: =E24*D24 -> 1.6236
B25: NPK đubrivo 15:15:15 | D25: 0.34 | E25: 300 | F25: =E25*D25 -> 102
A26: 16 | B26: II međuredno kultiviranje sa đubrenjem | C26: XI | D26: 1.23 | E26: 2.92 | F26: =E26*D26 -> 3.5916
A27: UKUPNI TROŠKOVI | F27: =SUM(F5:F26) -> 317.3338 | G27: =F1*F27 -> 0
A28: Potrošnja goriva | E28: =E5+E6+E7+E9+E10+E11+E12+E14+E15+E16+E18+E20+E21+E22+E23+E24+E26 -> 38.46 | G28: Ukupno
A30: Komorač je višegodišnja zeljasta biljka, visine 150-200 cm. Dužina gajenja varira od 5 do 10 godina. Gaji se zbog ploda od koga se proizvodi eterično ulje. Koristi se u kozmetičkoj i prehrambenoj industriji, kao sredstvo za popravljanje mirisa, za izradu čajeva, likera, bombona i sl. Setva se obavlja mašinski rano u proleće, sa 10-12 kg semena po hektaru, međurednim razmakom od 60-70 cm, dok na dužni metar treba da bude raspoređeno oko 50 semenki na dubinu od 2-3 cm i sa 50-70 klijavih zrna na dužni metar. Žetva se obavlja žitnim kombajnom u jednom prohodu. Prinos se kreće od 2,5-2,7 t/ha ili 1-2 t/ha suvog ploda ili 25-30 kg eteričnog ulja. U toku zime nadzemni deo biljke propada i obnavlja se u proleće svake godine. Na kraju vegetacije obavlja se košenje nadzemnog dela i prihranjivanje sa međurednim kultiviranjem.
B39: NANA (MENTA) | D39: Obradivo zemljište (ha): | F39: 0
A41: KLIJENT | E41: OPTIMALNO
A42: R. br. | B42: Tehnološke operacije i korišćeni materijal | C42: Operacija u mesecu | D42: Trošak po kg ili litru (EUR) | E42: Optimalna potrošnja kg ili l/ha | F42: Optimalni troškovi tehnoloških operacija/ha (EUR)
A43: 1 | B43: Utovar stajnjaka (1/2) | C43: VII | D43: 1.23 | E43: 2.83 | F43: =E43*D43 -> 3.4809
A44: 2 | B44: Transport i rasturanje stajnjaka (1/2) | C44: VII | D44: 1.23 | E44: 15 | F44: =E44*D44 -> 18.45
A45: 3 | B45: Zaoravanje strnjike (1/2) | C45: VII | D45: 1.23 | E45: 8.79 | F45: =E45*D45 -> 10.8117
A46: 4 | B46: Tanjiranje (1/2) | C46: IX | D46: 1.23 | E46: 1.95 | F46: =E46*D46 -> 2.3985
A47: 5 | B47: Transport đubriva | C47: X | D47: 1.23 | E47: 1.32 | F47: =E47*D47 -> 1.6236
B48: NPK đubrivo 15:15:15 | D48: 0.35 | E48: 300 | F48: =E48*D48 -> 105
A49: 6 | B49: Rasipanje mineralnih đubriva | C49: X | D49: 1.23 | E49: 0.96 | F49: =E49*D49 -> 1.1808
A50: 7 | B50: Oranje (1/2) | C50: X | D50: 1.23 | E50: 10.83 | F50: =E50*D50 -> 13.3209
A51: 8 | B51: Predsetvena priprema zemljišta (1/2) | C51: IV | D51: 1.23 | E51: 1.08 | F51: =E51*D51 -> 1.3284
...

Sheet Stočarstvo niži nivo intenz.
A2: Krave | B2: 0 | C2: Vet. troškovi | D2: 28.8 | E2: =B2*D2 -> 0 | G2: Junice | H2: 0 | I2: Vet. troškovi | J2: 29.16 | K2: =J2*H2 -> 0
A3: Hraniva | B3: Učešće hraniva u obroku % | C3: Ukupna potrošnja (kg) | G3: Hraniva | H3: Učešće hraniva u obroku % | I3: Ukupna potrošnja (kg)
A4: Kukuruz | B4: 100 | C4: =1825*B4/100*$B$2 -> 0 | G4: Kukuruz | H4: 100 | I4: =1460*H4/100*$H$2 -> 0
A5: Tritikale | B5: 0 | C5: =1825*B5/100*$B$2 -> 0 | G5: Tritikale | H5: 0 | I5: =1460*H5/100*$H$2 -> 0
A6: Pšenica | B6: 0 | C6: =1825*B6/100*$B$2 -> 0 | G6: Pšenica | H6: 0 | I6: =1460*H6/100*$H$2 -> 0
A7: Ovas | B7: 0 | C7: =1825*B7/100*$B$2 -> 0 | G7: Ovas | H7: 0 | I7: =1460*H7/100*$H$2 -> 0
A8: Raž | B8: 0 | C8: =1825*B8/100*$B$2 -> 0 | G8: Raž | H8: 0 | I8: =1460*H8/100*$H$2 -> 0
A9: Ječam | B9: 0 | C9: =1825*B9/100*$B$2 -> 0 | G9: Ječam | H9: 0 | I9: =1460*H9/100*$H$2 -> 0
A10: Suncokret | B10: 0 | C10: =1825*B10/100*$B$2 -> 0 | G10: Suncokret | H10: 0 | I10: =1460*H10/100*$H$2 -> 0
A11: Soja | B11: 0 | C11: =1825*B11/100*$B$2 -> 0 | G11: Soja | H11: 0 | I11: =1460*H11/100*$H$2 -> 0
B12: 0 | C12: =1825*B12/100*$B$2 -> 0 | H12: 0 | I12: =1460*H12/100*$H$2 -> 0
A13: Koncentrat I | B13: 0 | C13: =1825*B13/100*$B$2 -> 0 | G13: Koncentrat I | H13: 0 | I13: =1460*H13/100*$H$2 -> 0 | N13: ProCredit banka
A14: Silažni kukuruz | B14: 0 | C14: =3650*B14/100*$B$2 -> 0 | G14: Silažni kukuruz | H14: 0 | I14: =1460*H14/100*$H$2 -> 0 | N14: Prijepolje i Novi Pazar
A15: Kukuruzovina | B15: 0 | C15: =3650*B15/100*$B$2 -> 0 | G15: Kukuruzovina | H15: 0 | I15: =1460*H15/100*$H$2 -> 0
A16: Lucerka - seno | B16: 100 | C16: =3650*B16/100*$B$2 -> 0 | G16: Lucerka - seno | H16: 100 | I16: =1460*H16/100*$H$2 -> 0
A17: Livade - seno | B17: 0 | C17: =3650*B17/100*$B$2 -> 0 | G17: Livade - seno | H17: 0 | I17: =1460*H17/100*$H$2 -> 0
B18: =SUM(B4:B13) -> 100 | C18: % | H18: =SUM(H4:H13) -> 100 | I18: %
B19: =SUM(B14:B17) -> 100 | C19: % | H19: =SUM(H14:H17) -> 100 | I19: %
A20: Kupovna težina | B20: 150 | C20: Prodajna tež. | D20: 550 | E20: =(D20-B20)*5 -> 2000 | G20: Kupovna težina | H20: 10 | I20: Prodajna tež. | J20: 25 | K20: =(J20-H20)*2.2 -> 33
A21: Tovna junad | B21: 0 | C21: Vet. troškovi | D21: 18.24 | E21: =D21*B21 -> 0 | G21: Prasad | H21: 0 | I21: Vet. troškovi | J21: 4 | K21: =J21*H21 -> 0
A22: Hraniva | B22: Učešće hraniva u obroku % | C22: Ukupna potrošnja (kg) | G22: Hraniva | H22: Učešće hraniva u obroku % | I22: Ukupna potrošnja (kg)
A23: Kukuruz | B23: 100 | C23: =$E$20*B23/100*$B$21 -> 0 | G23: Kukuruz | H23: 100 | I23: =$K$20*H23/100*$H$21 -> 0
A24: Tritikale | B24: 0 | C24: =$E$20*B24/100*$B$21 -> 0 | G24: Tritikale | H24: 0 | I24: =$K$20*H24/100*$H$21 -> 0
A25: Pšenica | B25: 0 | C25: =$E$20*B25/100*$B$21 -> 0 | G25: Pšenica | H25: 0 | I25: =$K$20*H25/100*$H$21 -> 0
A26: Ovas | B26: 0 | C26: =$E$20*B26/100*$B$21 -> 0 | G26: Ovas | H26: 0 | I26: =$K$20*H26/100*$H$21 -> 0
A27: Raž | B27: 0 | C27: =$E$20*B27/100*$B$21 -> 0 | G27: Raž | H27: 0 | I27: =$K$20*H27/100*$H$21 -> 0
A28: Ječam | B28: 0 | C28: =$E$20*B28/100*$B$21 -> 0 | G28: Ječam | H28: 0 | I28: =$K$20*H28/100*$H$21 -> 0
A29: Suncokret | B29: 0 | C29: =$E$20*B29/100*$B$21 -> 0 | G29: Suncokret | H29: 0 | I29: =$K$20*H29/100*$H$21 -> 0
A30: Soja | B30: 0 | C30: =$E$20*B30/100*$B$21 -> 0 | G30: Soja | H30: 0 | I30: =$K$20*H30/100*$H$21 -> 0
A31: Concentrat I | B31: 0 | C31: =$E$20*B31/100*$B$21 -> 0 | H31: 0 | I31: =$K$20*H31/100*$H$21 -> 0
A32: Silažni kukuruz | B32: 0 | C32: =$E$20*B32/100*$B$21*1.8 -> 0 | H32: 0 | I32: =$K$20*H32/100*$H$21 -> 0
A33: Kukuruzovina | B33: 0 | C33: =$E$20*B33/100*$B$21*1.8 -> 0 | H33: 0 | I33: =$K$20*H33/100*$H$21 -> 0
A34: Lucerka - seno | B34: 100 | C34: =$E$20*B34/100*$B$21*1.8 -> 0 | G34: Concentrat II | H34: 0 | I34: =$K$20*H34/100*$H$21 -> 0
A35: Livade - seno | B35: 0 | C35: =$E$20*B35/100*$B$21*1.8 -> 0 | H35: =SUM(H23:H34) -> 100 | I35: %
B36: =SUM(B23:B31) -> 100 | C36: %
B37: =SUM(B32:B35) -> 100 | C37: % | G37: Kupovna težina | H37: 25 | I37: Prodajna tež. | J37: 110 | K37: =(J37-H37)*3.6 -> 306
A38: Krmače | B38: 0 | C38: Vet. troškovi | D38: 39.36 | E38: =D38*B38 -> 0 | G38: Tovne svinje | H38: 0 | I38: Vet. troškovi | J38: 3 | K38: =J38*H38 -> 0
A39: Hraniva | B39: Učešće hraniva u obroku % | C39: Ukupna potrošnja (kg) | G39: Hraniva | H39: Učešće hraniva u obroku % | I39: Ukupna potrošnja (kg)
A40: Kukuruz | B40: 100 | C40: =913*B40/100*$B$38 -> 0 | G40: Kukuruz | H40: 100 | I40: =$K$37*H40/100*$H$38 -> 0
A41: Tritikale | B41: 0 | C41: =913*B41/100*$B$38 -> 0 | G41: Tritikale | H41: 0 | I41: =$K$37*H41/100*$H$38 -> 0
...

Sheet Stočarstvo viši nivo intenz.
A2: Krave | B2: 0 | C2: Vet. troškovi | D2: 28.8 | E2: =B2*D2 -> 0 | G2: Junice | H2: 0 | I2: Vet. troškovi | J2: 29.16 | K2: =J2*H2 -> 0
A3: Hraniva | B3: Učešće hraniva u obroku % | C3: Ukupna potrošnja (kg) | G3: Hraniva | H3: Učešće hraniva u obroku % | I3: Ukupna potrošnja (kg)
A4: Kukuruz | B4: 100 | C4: =1825*B4/100*$B$2 -> 0 | G4: Kukuruz | H4: 100 | I4: =1460*H4/100*$H$2 -> 0
A5: Tritikale | B5: 0 | C5: =1825*B5/100*$B$2 -> 0 | G5: Tritikale | H5: 0 | I5: =1460*H5/100*$H$2 -> 0
A6: Pšenica | B6: 0 | C6: =1825*B6/100*$B$2 -> 0 | G6: Pšenica | H6: 0 | I6: =1460*H6/100*$H$2 -> 0
A7: Ovas | B7: 0 | C7: =1825*B7/100*$B$2 -> 0 | G7: Ovas | H7: 0 | I7: =1460*H7/100*$H$2 -> 0
A8: Raž | B8: 0 | C8: =1825*B8/100*$B$2 -> 0 | G8: Raž | H8: 0 | I8: =1460*H8/100*$H$2 -> 0
A9: Ječam | B9: 0 | C9: =1825*B9/100*$B$2 -> 0 | G9: Ječam | H9: 0 | I9: =1460*H9/100*$H$2 -> 0
A10: Suncokret | B10: 0 | C10: =1825*B10/100*$B$2 -> 0 | G10: Suncokret | H10: 0 | I10: =1460*H10/100*$H$2 -> 0
A11: Soja | B11: 0 | C11: =1825*B11/100*$B$2 -> 0 | G11: Soja | H11: 0 | I11: =1460*H11/100*$H$2 -> 0
B12: 0 | C12: =1825*B12/100*$B$2 -> 0 | H12: 0 | I12: =1460*H12/100*$H$2 -> 0
A13: Koncentrat I | B13: 0 | C13: =1825*B13/100*$B$2 -> 0 | G13: Koncentrat I | H13: 0 | I13: =1460*H13/100*$H$2 -> 0 | N13: ProCredit banka
A14: Silažni kukuruz | B14: 0 | C14: =5475*B14/100*$B$2 -> 0 | G14: Silažni kukuruz | H14: 0 | I14: =1460*H14/100*$H$2 -> 0 | N14: Prijepolje i Novi Pazar
A15: Kukuruzovina | B15: 0 | C15: =5475*B15/100*$B$2 -> 0 | G15: Kukuruzovina | H15: 0 | I15: =1460*H15/100*$H$2 -> 0
A16: Lucerka - seno | B16: 100 | C16: =5475*B16/100*$B$2 -> 0 | G16: Lucerka - seno | H16: 100 | I16: =1460*H16/100*$H$2 -> 0
A17: Livade - seno | B17: 0 | C17: =5475*B17/100*$B$2 -> 0 | G17: Livade - seno | H17: 0 | I17: =1460*H17/100*$H$2 -> 0
B18: =SUM(B4:B13) -> 100 | C18: % | H18: =SUM(H4:H13) -> 100 | I18: %
B19: =SUM(B14:B17) -> 100 | C19: % | H19: =SUM(H14:H17) -> 100 | I19: %
A20: Kupovna težina | B20: 150 | C20: Prodajna tež. | D20: 550 | E20: =(D20-B20)*3.6 -> 1440 | G20: Kupovna težina | H20: 10 | I20: Prodajna tež. | J20: 25 | K20: =(J20-H20)*2.1 -> 31.5
A21: Tovna junad | B21: 0 | C21: Vet. troškovi | D21: 18.24 | E21: =D21*B21 -> 0 | G21: Prasad | H21: 0 | I21: Vet. troškovi | J21: 4 | K21: =J21*H21 -> 0
A22: Hraniva | B22: Učešće hraniva u obroku % | C22: Ukupna potrošnja (kg) | G22: Hraniva | H22: Učešće hraniva u obroku % | I22: Ukupna potrošnja (kg)
A23: Kukuruz | B23: 100 | C23: =$E$20*B23/100*$B$21 -> 0 | G23: Kukuruz | H23: 100 | I23: =$K$20*H23/100*$H$21 -> 0
A24: Tritikale | B24: 0 | C24: =$E$20*B24/100*$B$21 -> 0 | G24: Tritikale | H24: 0 | I24: =$K$20*H24/100*$H$21 -> 0
A25: Pšenica | B25: 0 | C25: =$E$20*B25/100*$B$21 -> 0 | G25: Pšenica | H25: 0 | I25: =$K$20*H25/100*$H$21 -> 0
A26: Ovas | B26: 0 | C26: =$E$20*B26/100*$B$21 -> 0 | G26: Ovas | H26: 0 | I26: =$K$20*H26/100*$H$21 -> 0
A27: Raž | B27: 0 | C27: =$E$20*B27/100*$B$21 -> 0 | G27: Raž | H27: 0 | I27: =$K$20*H27/100*$H$21 -> 0
A28: Ječam | B28: 0 | C28: =$E$20*B28/100*$B$21 -> 0 | G28: Ječam | H28: 0 | I28: =$K$20*H28/100*$H$21 -> 0
A29: Suncokret | B29: 0 | C29: =$E$20*B29/100*$B$21 -> 0 | G29: Suncokret | H29: 0 | I29: =$K$20*H29/100*$H$21 -> 0
A30: Soja | B30: 0 | C30: =$E$20*B30/100*$B$21 -> 0 | G30: Soja | H30: 0 | I30: =$K$20*H30/100*$H$21 -> 0
A31: Concentrat I | B31: 0 | C31: =$E$20*B31/100*$B$21 -> 0 | H31: 0 | I31: =$K$20*H31/100*$H$21 -> 0
A32: Silažni kukuruz | B32: 0 | C32: =$E$20*B32/100*$B$21*2.7 -> 0 | H32: 0 | I32: =$K$20*H32/100*$H$21 -> 0
A33: Kukuruzovina | B33: 0 | C33: =$E$20*B33/100*$B$21*2.7 -> 0 | H33: 0 | I33: =$K$20*H33/100*$H$21 -> 0
A34: Lucerka - seno | B34: 100 | C34: =$E$20*B34/100*$B$21*2.7 -> 0 | G34: Concentrat II | H34: 0 | I34: =$K$20*H34/100*$H$21 -> 0
A35: Livade - seno | B35: 0 | C35: =$E$20*B35/100*$B$21*2.7 -> 0 | H35: =SUM(H23:H34) -> 100 | I35: %
B36: =SUM(B23:B31) -> 100 | C36: %
B37: =SUM(B32:B35) -> 100 | C37: % | G37: Kupovna težina | H37: 25 | I37: Prodajna tež. | J37: 110 | K37: =(J37-H37)*3.5 -> 297.5
A38: Krmače | B38: 0 | C38: Vet. troškovi | D38: 39.36 | E38: =D38*B38 -> 0 | G38: Tovne svinje | H38: 0 | I38: Vet. troškovi | J38: 3 | K38: =J38*H38 -> 0
A39: Hraniva | B39: Učešće hraniva u obroku % | C39: Ukupna potrošnja (kg) | G39: Hraniva | H39: Učešće hraniva u obroku % | I39: Ukupna potrošnja (kg)
A40: Kukuruz | B40: 100 | C40: =1095*B40/100*$B$38 -> 0 | G40: Kukuruz | H40: 100 | I40: =$K$37*H40/100*$H$38 -> 0
A41: Tritikale | B41: 0 | C41: =1095*B41/100*$B$38 -> 0 | G41: Tritikale | H41: 0 | I41: =$K$37*H41/100*$H$38 -> 0
...

Sheet Priručnik
A1: RATARSKE KULTURE | D1: TROŠAK €/ha | H1: VOĆARSKE KULTURE | K1: TROŠAK €/ha
A2: JEČAM | D2: =Usevi!F27 -> 355.5774 | H2: ŠLJIVA - ekstenzivan zasad | K2: =Voće!F19 -> 208.347
A3: PŠENICA | D3: =Usevi!F62 -> 406.3616 | H3: ŠLJIVA - intenzivan zasad | K3: =Voće!F52 -> 935.702
A4: TRITIKALE | D4: =Usevi!F95 -> 387.9192 | H4: JABUKA - ekstenzivan zasad | K4: =Voće!F81 -> 411.9212
A5: KUKURUZ | D5: =Usevi!F131 -> 408.6432 | H5: JABUKA - intenzivan zasad | K5: =Voće!F131 -> 1329.5435
A6: SILAŽNI KUKURUZ | D6: =Usevi!F166 -> 462.6648 | H6: KRUŠKA | K6: =Voće!F178 -> 1108.5369
A7: SUNCOKRET | D7: =Usevi!F199 -> 318.9074 | H7: BRESKVA | K7: =Voće!F212 -> 844.9134
A8: ŠEĆERNA REPA | D8: =Usevi!F236 -> 735.1955 | H8: KAJSIJA | K8: =Voće!F237 -> 422.3535
A9: SOJA | D9: =Usevi!F276 -> 383.5099 | H9: VINOGRAD | K9: =Voće!F278 -> 1152.6194
A10: STOČNI GRAŠAK | D10: =Usevi!F304 -> 323.2154 | H10: MALINA I KUPINA | K10: =Voće!F308 -> 1119.12
A11: LUCERKA | D11: =Usevi!F339 -> 142.747 | H11: VIŠNJA | K11: =Voće!F343 -> 802.2194
A12: RAŽ | D12: =Usevi!F373 -> 343.5774 | H12: JAGODA | K12: =Voće!F369 -> 617.6016
A13: OVAS | D13: =Usevi!F406 -> 343.5774 | H13: DUNJA | K13: =Voće!F394 -> 232.1234
A14: ULJANA REPICA | D14: =Usevi!F434 -> 277.9206 | H14: MUŠMULA | K14: =Voće!F419 -> 232.1234
A15: DUVAN | D15: =Usevi!F478 -> 665.20694 | H15: LEŠNIK | K15: =Voće!F454 -> 545.8056
A16: HELJDA | D16: =Usevi!F501 -> 934.1568
H17: PLASTENICI | K17: TROŠAK €/struku, €/kg
A18: POVRTARSKE KULTURE | D18: TROŠAK €/ha | H18: PARADAJZ | K18: =Plastenici!H24 -> 0.4056499
A19: KROMPIR | D19: =Povrće!F37 -> 2559.1695 | H19: PAPRIKA SLATKA | K19: =Plastenici!H51 -> 0.23506723
A20: PASULJ | D20: =Povrće!F78 -> 1137.9293 | H20: PAPRIKA LJUTA | K20: =Plastenici!H78 -> 0.24548421
A21: ROTKVICA | D21: =Povrće!F109 -> 1332.1603 | H21: KRASTAVAC | K21: =Plastenici!H107 -> 0.49927569
